{"errorMessage": "An error occurred (ResourceNotFoundException) when calling the PutItem operation: Requested resource not found", "errorType": "ResourceNotFoundException", "stackTrace": ["  File \"/var/task/index.py\", line 78, in lambda_handler\n    data = save_to_ddb(ddb_payload)\n", "  File \"/var/task/index.py\", line 45, in save_to_ddb\n    return client.put_item(\n", "  File \"/var/runtime/botocore/client.py\", line 530, in _api_call\n    return self._make_api_call(operation_name, kwargs)\n", "  File \"/var/runtime/botocore/client.py\", line 960, in _make_api_call\n    raise error_class(parsed_response, operation_name)\n"]}